Workbook

Sheet Totalpopulation
A1: De jure Population number1 of the Republic of Armenia, as of 1 January
A2: TOTAL POPULATION
M3: /person/
A4: Marz, district, city/town, administrative districts | B4: 2011 2 | C4: 2012 | D4: 2013 | E4: 2014 | F4: 2015 | G4: 2016 | H4: 2017 | I4: 2018 | J4: 2019 | K4: 2020 | L4: 2021 | M4: 2022
A5: Republic of Armenia | B5: =B6+B8+B14+B19+B24+B31+B39+B44+B52+B58+B62 -> 3018854 | C5: =C6+C8+C14+C19+C24+C31+C39+C44+C52+C58+C62 -> 3021376 | D5: =D6+D8+D14+D19+D24+D31+D39+D44+D52+D58+D62 -> 3026879 | E5: =E6+E8+E14+E19+E24+E31+E39+E44+E52+E58+E62 -> 3017079 | F5: =F6+F8+F14+F19+F24+F31+F39+F44+F52+F58+F62 -> 3010598 | G5: =G6+G8+G14+G19+G24+G31+G39+G44+G52+G58+G62 -> 2998577 | H5: =H6+H8+H14+H19+H24+H31+H39+H44+H52+H58+H62 -> 2986151 | I5: =I6+I8+I14+I19+I24+I31+I39+I44+I52+I58+I62 -> 2972732 | ... M5: =M6+M8+M14+M19+M24+M31+M39+M44+M52+M58+M62 -> 2961367
A6: City Yerevan | B6: =Urbanpopulation!B6 -> 1060138 | C6: =Urbanpopulation!C6 -> 1061044 | D6: =Urbanpopulation!D6 -> 1066264 | E6: =Urbanpopulation!E6 -> 1068306 | F6: =Urbanpopulation!F6 -> 1071511 | G6: =[1]Քաղաքային!G6 -> 1073660 | H6: =[2]Քաղաքային!H6 -> 1075841 | I6: =[3]Քաղաքային!I6 -> 1077590 | J6: =[4]Քաղաքային!J6 -> 1081874 | K6: =[5]Քաղաքային!K6 -> 1084024 | L6: =[6]Քաղաքային!L6 -> 1091747 | M6: =[7]Քաղաքային!M6 -> 1092778
A8: Aragatsotn Marz | B8: =B9+B10+B11+B12 -> 132925 | C8: =C9+C10+C11+C12 -> 133063 | D8: =D9+D10+D11+D12 -> 133070 | E8: =E9+E10+E11+E12 -> 132305 | F8: =F9+F10+F11+F12 -> 131332 | G8: =G9+G10+G11+G12 -> 129774 | H8: =H9+H10+H11+H12 -> 128518 | I8: =I9+I10+I11+I12 -> 127146 | ... M8: =M9+M10+M11+M12 -> 124646
A9: Ashtarak district | B9: =[8]Քաղաքային!B21+[8]Գյուղական!B8 -> 64287 | C9: =[8]Քաղաքային!C21+[8]Գյուղական!C8 -> 64325 | D9: =[8]Քաղաքային!D21+[8]Գյուղական!D8 -> 64174 | E9: =[8]Քաղաքային!E21+[8]Գյուղական!E8 -> 63546 | F9: =[8]Քաղաքային!F21+[8]Գյուղական!F8 -> 62759 | G9: =[8]Քաղաքային!G21+[8]Գյուղական!G8 -> 61709 | H9: =[8]Քաղաքային!H21+[8]Գյուղական!H8 -> 60834 | I9: =[3]Քաղաքային!I21+[3]Գյուղական!I8 -> 59916 | J9: 58799 | K9: =[5]Քաղաքային!K21+[5]Գյուղական!K8 -> 58322 | L9: =[6]Քաղաքային!L21+[6]Գյուղական!L8 -> 58261 | M9: =[7]Քաղաքային!M21+[7]Գյուղական!M8 -> 58319
A10: Aparan district | B10: =[8]Քաղաքային!B22+[8]Գյուղական!B9 -> 22029 | C10: =[8]Քաղաքային!C22+[8]Գյուղական!C9 -> 22062 | D10: =[8]Քաղաքային!D22+[8]Գյուղական!D9 -> 22118 | E10: =[8]Քաղաքային!E22+[8]Գյուղական!E9 -> 22081 | F10: =[8]Քաղաքային!F22+[8]Գյուղական!F9 -> 21975 | G10: =[8]Քաղաքային!G22+[8]Գյուղական!G9 -> 21770 | H10: =[8]Քաղաքային!H22+[8]Գյուղական!H9 -> 21623 | I10: =[3]Քաղաքային!I22+[3]Գյուղական!I9 -> 21446 | J10: =[4]Քաղաքային!J22+[4]Գյուղական!J9 -> 21184 | K10: =[5]Քաղաքային!K22+[5]Գյուղական!K9 -> 21128 | L10: =[6]Քաղաքային!L22+[6]Գյուղական!L9 -> 21071 | M10: =[7]Քաղաքային!M22+[7]Գյուղական!M9 -> 21122
A11: Aragats district | B11: =[8]Գյուղական!B10 -> 13250 | C11: =[8]Գյուղական!C10 -> 13276 | D11: =[8]Գյուղական!D10 -> 13361 | E11: =[8]Գյուղական!E10 -> 13378 | F11: =[8]Գյուղական!F10 -> 13448 | G11: =[8]Գյուղական!G10 -> 13485 | H11: =[8]Գյուղական!H10 -> 13530 | I11: =[3]Գյուղական!I10 -> 13553 | J11: =[4]Գյուղական!J10 -> 13522 | K11: =[5]Գյուղական!K10 -> 13526 | L11: =[6]Գյուղական!L10 -> 13463 | M11: =[7]Գյուղական!M10 -> 13494
A12: Talin district | B12: =[8]Քաղաքային!B23+[8]Գյուղական!B11 -> 33359 | C12: =[8]Քաղաքային!C23+[8]Գյուղական!C11 -> 33400 | D12: =[8]Քաղաքային!D23+[8]Գյուղական!D11 -> 33417 | E12: =[8]Քաղաքային!E23+[8]Գյուղական!E11 -> 33300 | F12: =[8]Քաղաքային!F23+[8]Գյուղական!F11 -> 33150 | G12: =[8]Քաղաքային!G23+[8]Գյուղական!G11 -> 32810 | H12: =[8]Քաղաքային!H23+[8]Գյուղական!H11 -> 32531 | I12: =[3]Քաղաքային!I23+[3]Գյուղական!I11 -> 32231 | J12: =[4]Քաղաքային!J23+[4]Գյուղական!J11 -> 31935 | K12: =[5]Քաղաքային!K23+[5]Գյուղական!K11 -> 31745 | L12: =[6]Քաղաքային!L23+[6]Գյուղական!L11 -> 31651 | M12: =[7]Քաղաքային!M23+[7]Գյուղական!M11 -> 31711
A14: Ararat marz | B14: =B15+B16+B17 -> 260367 | C14: =C15+C16+C17 -> 260634 | D14: =D15+D16+D17 -> 261335 | E14: =E15+E16+E17 -> 260787 | F14: =F15+F16+F17 -> 260102 | G14: =G15+G16+G17 -> 258911 | H14: =H15+H16+H17 -> 258407 | I14: =I15+I16+I17 -> 257804 | ... M14: =M15+M16+M17 -> 256615
A15: Artashat district | B15: =[8]Քաղաքային!B26+[8]Գյուղական!B14 -> 93013 | C15: =[8]Քաղաքային!C26+[8]Գյուղական!C14 -> 93072 | D15: =[8]Քաղաքային!D26+[8]Գյուղական!D14 -> 93046 | E15: =[8]Քաղաքային!E26+[8]Գյուղական!E14 -> 92321 | F15: =[8]Քաղաքային!F26+[8]Գյուղական!F14 -> 91537 | G15: =[8]Քաղաքային!G26+[8]Գյուղական!G14 -> 90409 | H15: =[8]Քաղաքային!H26+[8]Գյուղական!H14 -> 89804 | I15: =[3]Քաղաքային!I26+[3]Գյուղական!I14 -> 89070 | J15: =[4]Քաղաքային!J26+[4]Գյուղական!J14 -> 88118 | K15: =[5]Քաղաքային!K26+[5]Գյուղական!K14 -> 87820 | L15: =[6]Քաղաքային!L26+[6]Գյուղական!L14 -> 87633 | M15: =[7]Քաղաքային!M26+[7]Գյուղական!M14 -> 87476
A16: Ararat district | B16: =[8]Քաղաքային!B27+[8]Քաղաքային!B28+[8]Գյուղական!B15 -> 88912 | C16: =[8]Քաղաքային!C27+[8]Քաղաքային!C28+[8]Գյուղական!C15 -> 89071 | D16: =[8]Քաղաքային!D27+[8]Քաղաքային!D28+[8]Գյուղական!D15 -> 89509 | E16: =[8]Քաղաքային!E27+[8]Քաղաքային!E28+[8]Գյուղական!E15 -> 89579 | F16: =[8]Քաղաքային!F27+[8]Քաղաքային!F28+[8]Գյուղական!F15 -> 89577 | G16: =[8]Քաղաքային!G27+[8]Քաղաքային!G28+[8]Գյուղական!G15 -> 89526 | H16: =[8]Քաղաքային!H27+[8]Քաղաքային!H28+[8]Գյուղական!H15 -> 89617 | I16: =[3]Քաղաքային!I27+[3]Քաղաքային!I28+[3]Գյուղական!I15 -> 89759 | J16: =[4]Քաղաքային!J27+[4]Քաղաքային!J28+[4]Գյուղական!J15 -> 89626 | K16: =[5]Քաղաքային!K27+[5]Քաղաքային!K28+[5]Գյուղական!K15 -> 89694 | L16: =[6]Քաղաքային!L27+[6]Քաղաքային!L28+[6]Գյուղական!L15 -> 89675 | M16: =[7]Քաղաքային!M27+[7]Քաղաքային!M28+[7]Գյուղական!M15 -> 89721
A17: Masis district | B17: =[8]Քաղաքային!B29+[8]Գյուղական!B16 -> 78442 | C17: =[8]Քաղաքային!C29+[8]Գյուղական!C16 -> 78491 | D17: =[8]Քաղաքային!D29+[8]Գյուղական!D16 -> 78780 | E17: =[8]Քաղաքային!E29+[8]Գյուղական!E16 -> 78887 | F17: =[8]Քաղաքային!F29+[8]Գյուղական!F16 -> 78988 | G17: =[8]Քաղաքային!G29+[8]Գյուղական!G16 -> 78976 | H17: =[8]Քաղաքային!H29+[8]Գյուղական!H16 -> 78986 | I17: =[3]Քաղաքային!I29+[3]Գյուղական!I16 -> 78975 | J17: =[4]Քաղաքային!J29+[4]Գյուղական!J16 -> 78944 | K17: =[5]Քաղաքային!K29+[5]Գյուղական!K16 -> 79056 | L17: =[6]Քաղաքային!L29+[6]Գյուղական!L16 -> 79322 | M17: =[7]Քաղաքային!M29+[7]Գյուղական!M16 -> 79418
A19: Armavir Marz | B19: =B20+B21+B22 -> 265770 | C19: =C20+C21+C22 -> 266151 | D19: =D20+D21+D22 -> 267101 | E19: =E20+E21+E22 -> 267187 | F19: =F20+F21+F22 -> 267002 | G19: =G20+G21+G22 -> 266613 | H19: =H20+H21+H22 -> 265759 | I19: =I20+I21+I22 -> 264617 | ... M19: =M20+M21+M22 -> 264383
A20: Armavir district | B20: =[8]Քաղաքային!B32+[8]Քաղաքային!B33+[8]Գյուղական!B19 -> 112092 | C20: =[8]Քաղաքային!C32+[8]Քաղաքային!C33+[8]Գյուղական!C19 -> 112265 | D20: =[8]Քաղաքային!D32+[8]Քաղաքային!D33+[8]Գյուղական!D19 -> 112691 | E20: =[8]Քաղաքային!E32+[8]Քաղաքային!E33+[8]Գյուղական!E19 -> 112884 | F20: =[8]Քաղաքային!F32+[8]Քաղաքային!F33+[8]Գյուղական!F19 -> 112821 | G20: =[8]Քաղաքային!G32+[8]Քաղաքային!G33+[8]Գյուղական!G19 -> 112582 | H20: =[8]Քաղաքային!H32+[8]Քաղաքային!H33+[8]Գյուղական!H19 -> 112189 | I20: =[3]Քաղաքային!I32+[3]Քաղաքային!I33+[3]Գյուղական!I19 -> 111693 | J20: =[4]Քաղաքային!J32+[4]Քաղաքային!J33+[4]Գյուղական!J19 -> 111459 | K20: =[5]Քաղաքային!K32+[5]Քաղաքային!K33+[5]Գյուղական!K19 -> 111479 | L20: =[6]Քաղաքային!L32+[6]Քաղաքային!L33+[6]Գյուղական!L19 -> 111347 | M20: =[7]Քաղաքային!M32+[7]Քաղաքային!M33+[7]Գյուղական!M19 -> 111725
A21: Baghramyan district | B21: =[8]Գյուղական!B20 -> 20291 | C21: =[8]Գյուղական!C20 -> 20336 | D21: =[8]Գյուղական!D20 -> 20415 | E21: =[8]Գյուղական!E20 -> 20190 | F21: =[8]Գյուղական!F20 -> 20071 | G21: =[8]Գյուղական!G20 -> 19973 | H21: =[8]Գյուղական!H20 -> 19721 | I21: =[3]Գյուղական!I20 -> 19506 | J21: =[4]Գյուղական!J20 -> 19302 | K21: =[5]Գյուղական!K20 -> 19230 | L21: =[6]Գյուղական!L20 -> 19198 | M21: =[7]Գյուղական!M20 -> 19165
A22: Echmiatsin district | B22: =[8]Քաղաքային!B34+[8]Գյուղական!B21 -> 133387 | C22: =[8]Քաղաքային!C34+[8]Գյուղական!C21 -> 133550 | D22: =[8]Քաղաքային!D34+[8]Գյուղական!D21 -> 133995 | E22: =[8]Քաղաքային!E34+[8]Գյուղական!E21 -> 134113 | F22: =[8]Քաղաքային!F34+[8]Գյուղական!F21 -> 134110 | G22: =[8]Քաղաքային!G34+[8]Գյուղական!G21 -> 134058 | H22: =[8]Քաղաքային!H34+[8]Գյուղական!H21 -> 133849 | I22: =[3]Քաղաքային!I34+[3]Գյուղական!I21 -> 133418 | J22: =[4]Քաղաքային!J34+[4]Գյուղական!J21 -> 133139 | K22: =[5]Քաղաքային!K34+[5]Գյուղական!K21 -> 133154 | L22: =[6]Քաղաքային!L34+[6]Գյուղական!L21 -> 133399 | M22: =[7]Քաղաքային!M34+[7]Գյուղական!M21 -> 133493
A24: Gegharkunik Marz | B24: =B25+B26+B27+B28+B29 -> 235075 | C24: =C25+C26+C27+C28+C29 -> 235380 | D24: =D25+D26+D27+D28+D29 -> 235587 | E24: =E25+E26+E27+E28+E29 -> 234079 | F24: =F25+F26+F27+F28+F29 -> 232988 | G24: =G25+G26+G27+G28+G29 -> 231794 | H24: =H25+H26+H27+H28+H29 -> 230715 | I24: =I25+I26+I27+I28+I29 -> 229711 | ... M24: =M25+M26+M27+M28+M29 -> 227778
A25: Gavar district | B25: =[8]Քաղաքային!B37+[8]Գյուղական!B24 -> 52687 | C25: =[8]Քաղաքային!C37+[8]Գյուղական!C24 -> 52727 | D25: =[8]Քաղաքային!D37+[8]Գյուղական!D24 -> 52601 | E25: =[8]Քաղաքային!E37+[8]Գյուղական!E24 -> 51990 | F25: =[8]Քաղաքային!F37+[8]Գյուղական!F24 -> 51420 | G25: =[8]Քաղաքային!G37+[8]Գյուղական!G24 -> 50744 | H25: =[8]Քաղաքային!H37+[8]Գյուղական!H24 -> 50176 | I25: =[3]Քաղաքային!I37+[3]Գյուղական!I24 -> 49659 | J25: =[4]Քաղաքային!J37+[4]Գյուղական!J24 -> 49039 | K25: =[5]Քաղաքային!K37+[5]Գյուղական!K24 -> 48625 | L25: =[6]Քաղաքային!L37+[6]Գյուղական!L24 -> 48472 | M25: =[7]Քաղաքային!M37+[7]Գյուղական!M24 -> 48440
A26: Chambarak district | B26: =[8]Քաղաքային!B38+[8]Գյուղական!B25 -> 13788 | C26: =[8]Քաղաքային!C38+[8]Գյուղական!C25 -> 13775 | D26: =[8]Քաղաքային!D38+[8]Գյուղական!D25 -> 13743 | E26: =[8]Քաղաքային!E38+[8]Գյուղական!E25 -> 13642 | F26: =[8]Քաղաքային!F38+[8]Գյուղական!F25 -> 13558 | G26: =[8]Քաղաքային!G38+[8]Գյուղական!G25 -> 13466 | H26: =[8]Քաղաքային!H38+[8]Գյուղական!H25 -> 13395 | I26: =[3]Քաղաքային!I38+[3]Գյուղական!I25 -> 13341 | J26: =[4]Քաղաքային!J38+[4]Գյուղական!J25 -> 13243 | K26: =[5]Քաղաքային!K38+[5]Գյուղական!K25 -> 13167 | L26: =[6]Քաղաքային!L38+[6]Գյուղական!L25 -> 13056 | M26: =[7]Քաղաքային!M38+[7]Գյուղական!M25 -> 13089
A27: Martuni district | B27: =[8]Քաղաքային!B39+[8]Գյուղական!B26 -> 90224 | C27: =[8]Քաղաքային!C39+[8]Գյուղական!C26 -> 90461 | D27: =[8]Քաղաքային!D39+[8]Գյուղական!D26 -> 90660 | E27: =[8]Քաղաքային!E39+[8]Գյուղական!E26 -> 90117 | F27: =[8]Քաղաքային!F39+[8]Գյուղական!F26 -> 89858 | G27: =[8]Քաղաքային!G39+[8]Գյուղական!G26 -> 89602 | H27: =[8]Քաղաքային!H39+[8]Գյուղական!H26 -> 89303 | I27: =[3]Քաղաքային!I39+[3]Գյուղական!I26 -> 89028 | J27: =[4]Քաղաքային!J39+[4]Գյուղական!J26 -> 88623 | K27: =[5]Քաղաքային!K39+[5]Գյուղական!K26 -> 88553 | L27: =[6]Քաղաքային!L39+[6]Գյուղական!L26 -> 88707 | M27: =[7]Քաղաքային!M39+[7]Գյուղական!M26 -> 89150
A28: Sevan district | B28: =[8]Քաղաքային!B40+[8]Գյուղական!B27 -> 39776 | C28: =[8]Քաղաքային!C40+[8]Գյուղական!C27 -> 39841 | D28: =[8]Քաղաքային!D40+[8]Գյուղական!D27 -> 40019 | E28: =[8]Քաղաքային!E40+[8]Գյուղական!E27 -> 40021 | F28: =[8]Քաղաքային!F40+[8]Գյուղական!F27 -> 40035 | G28: =[8]Քաղաքային!G40+[8]Գյուղական!G27 -> 40010 | H28: =[8]Քաղաքային!H40+[8]Գյուղական!H27 -> 39986 | I28: =[3]Քաղաքային!I40+[3]Գյուղական!I27 -> 39972 | J28: =[4]Քաղաքային!J40+[4]Գյուղական!J27 -> 39899 | K28: =[5]Քաղաքային!K40+[5]Գյուղական!K27 -> 39907 | L28: =[6]Քաղաքային!L40+[6]Գյուղական!L27 -> 39873 | M28: =[7]Քաղաքային!M40+[7]Գյուղական!M27 -> 39856
A29: Vardenis district | B29: =[8]Քաղաքային!B41+[8]Գյուղական!B28 -> 38600 | C29: =[8]Քաղաքային!C41+[8]Գյուղական!C28 -> 38576 | D29: =[8]Քաղաքային!D41+[8]Գյուղական!D28 -> 38564 | E29: =[8]Քաղաքային!E41+[8]Գյուղական!E28 -> 38309 | F29: =[8]Քաղաքային!F41+[8]Գյուղական!F28 -> 38117 | G29: =[8]Քաղաքային!G41+[8]Գյուղական!G28 -> 37972 | H29: =[8]Քաղաքային!H41+[8]Գյուղական!H28 -> 37855 | I29: =[3]Քաղաքային!I41+[3]Գյուղական!I28 -> 37711 | J29: =[4]Քաղաքային!J41+[4]Գյուղական!J28 -> 37452 | K29: =[5]Քաղաքային!K41+[5]Գյուղական!K28 -> 37380 | L29: =[6]Քաղաքային!L41+[6]Գյուղական!L28 -> 37161 | M29: =[7]Քաղաքային!M41+[7]Գյուղական!M28 -> 37243
A31: Lori Marz | B31: =B32+B33+B34+B35+B36+B37 -> 235537 | C31: =C32+C33+C34+C35+C36+C37 -> 235660 | D31: =D32+D33+D34+D35+D36+D37 -> 234663 | E31: =E32+E33+E34+E35+E36+E37 -> 230760 | F31: =F32+F33+F34+F35+F36+F37 -> 227999 | G31: =G32+G33+G34+G35+G36+G37 -> 224954 | H31: =H32+H33+H34+H35+H36+H37 -> 221098 | I31: =I32+I33+I34+I35+I36+I37 -> 217363 | ... M31: =M32+M33+M34+M35+M36+M37 -> 211677
A32: c.Vanadzor (Marz Center) | B32: 86199 | C32: 86202 | D32: 85673 | E32: 84298 | F32: 83385 | G32: 82221 | H32: 80703 | I32: =[3]Քաղաքային!I44 -> 79310 | J32: =[4]Քաղաքային!J44 -> 78386 | K32: =[5]Քաղաքային!K44 -> 77234 | L32: =[6]Քաղաքային!L44 -> 76860 | M32: =[7]Քաղաքային!M44 -> 76220
A33: Gugark district | B33: 22675 | C33: 22675 | D33: 22462 | E33: 21755 | F33: 21184 | G33: 20634 | H33: 20018 | I33: =[3]Գյուղական!I31 -> 19411 | J33: =[4]Գյուղական!J31 -> 19158 | K33: =[5]Գյուղական!K31 -> 18967 | L33: =[6]Գյուղական!L31 -> 19012 | M33: =[7]Գյուղական!M31 -> 19008
A34: Tumanyan district | B34: 40006 | C34: 39982 | D34: 39887 | E34: 39559 | F34: 39336 | G34: 39140 | H34: 38817 | I34: =[3]Քաղաքային!I45+[3]Քաղաքային!I46+[3]Քաղաքային!I47+[3]Քաղաքային!I48+[3]Գյուղական!I32 -> 38459 | J34: =[4]Քաղաքային!J45+[4]Քաղաքային!J46+[4]Քաղաքային!J47+[4]Քաղաքային!J48+[4]Գյուղական!J32 -> 38235 | K34: =[5]Քաղաքային!K45+[5]Քաղաքային!K46+[5]Քաղաքային!K47+[5]Քաղաքային!K48+[5]Գյուղական!K32 -> 37992 | L34: =[6]Քաղաքային!L45+[6]Քաղաքային!L46+[6]Քաղաքային!L47+[6]Քաղաքային!L48+[6]Գյուղական!L32 -> 37712 | M34: =[7]Քաղաքային!M45+[7]Քաղաքային!M46+[7]Քաղաքային!M47+[7]Քաղաքային!M48+[7]Գյուղական!M32 -> 37532
A35: Spitak district | B35: 36230 | C35: 36314 | D35: 36443 | E35: 36214 | F35: 36172 | G35: 36073 | H35: 35818 | I35: =[3]Քաղաքային!I49+[3]Գյուղական!I33 -> 35566 | J35: =[4]Քաղաքային!J49+[4]Գյուղական!J33 -> 35553 | K35: =[5]Քաղաքային!K49+[5]Գյուղական!K33 -> 35500 | L35: =[6]Քաղաքային!L49+[6]Գյուղական!L33 -> 35412 | M35: =[7]Քաղաքային!M49+[7]Գյուղական!M33 -> 35470
A36: Stepanavan district | B36: 28242 | C36: 28253 | D36: 28184 | E36: 27755 | F36: 27414 | G36: 27065 | H36: 26666 | I36: =[3]Քաղաքային!I50+[3]Գյուղական!I34 -> 26295 | J36: =[4]Քաղաքային!J50+[4]Գյուղական!J34 -> 26129 | K36: =[5]Քաղաքային!K50+[5]Գյուղական!K34 -> 25931 | L36: =[6]Քաղաքային!L50+[6]Գյուղական!L34 -> 25814 | M36: =[7]Քաղաքային!M50+[7]Գյուղական!M34 -> 25715
A37: Tashir district | B37: 22185 | C37: 22234 | D37: 22014 | E37: 21179 | F37: 20508 | G37: 19821 | H37: 19076 | I37: =[3]Քաղաքային!I51+[3]Գյուղական!I35 -> 18322 | J37: =[4]Քաղաքային!J51+[4]Գյուղական!J35 -> 18010 | K37: =[5]Քաղաքային!K51+[5]Գյուղական!K35 -> 17691 | L37: =[6]Քաղաքային!L51+[6]Գյուղական!L35 -> 17756 | M37: =[7]Քաղաքային!M51+[7]Գյուղական!M35 -> 17732
A39: Kotayk Marz | B39: =B40+B41+B42 -> 254397 | C39: =C40+C41+C42 -> 254616 | D39: =D40+D41+D42 -> 255353 | E39: =E40+E41+E42 -> 254997 | F39: =F40+F41+F42 -> 254990 | G39: =G40+G41+G42 -> 253898 | H39: =H40+H41+H42 -> 252830 | I39: =I40+I41+I42 -> 251598 | ... M39: =M40+M41+M42 -> 251076
A40: Hrazdan district | B40: =[8]Քաղաքային!B54+[8]Քաղաքային!B55+[8]Քաղաքային!B56+[8]Գյուղական!B38 -> 85339 | C40: =[8]Քաղաքային!C54+[8]Քաղաքային!C55+[8]Քաղաքային!C56+[8]Գյուղական!C38 -> 85445 | D40: =[8]Քաղաքային!D54+[8]Քաղաքային!D55+[8]Քաղաքային!D56+[8]Գյուղական!D38 -> 85580 | E40: =[8]Քաղաքային!E54+[8]Քաղաքային!E55+[8]Քաղաքային!E56+[8]Գյուղական!E38 -> 85210 | F40: =[8]Քաղաքային!F54+[8]Քաղաքային!F55+[8]Քաղաքային!F56+[8]Գյուղական!F38 -> 85140 | G40: =[8]Քաղաքային!G54+[8]Քաղաքային!G55+[8]Քաղաքային!G56+[8]Գյուղական!G38 -> 84430 | H40: =[8]Քաղաքային!H54+[8]Քաղաքային!H55+[8]Քաղաքային!H56+[8]Գյուղական!H38 -> 83807 | I40: =[3]Քաղաքային!I54+[3]Քաղաքային!I55+[3]Քաղաքային!I56+[3]Գյուղական!I38 -> 83200 | J40: =[4]Քաղաքային!J54+[4]Քաղաքային!J55+[4]Քաղաքային!J56+[4]Գյուղական!J38 -> 83140 | K40: =[5]Քաղաքային!K54+[5]Քաղաքային!K55+[5]Քաղաքային!K56+[5]Գյուղական!K38 -> 82609 | L40: =[6]Քաղաքային!L54+[6]Քաղաքային!L55+[6]Քաղաքային!L56+[6]Գյուղական!L38 -> 82477 | M40: =[7]Քաղաքային!M54+[7]Քաղաքային!M55+[7]Քաղաքային!M56+[7]Գյուղական!M38 -> 82456
A41: Kotayk district | B41: =[8]Քաղաքային!B57+[8]Քաղաքային!B58+[8]Գյուղական!B39 -> 111089 | C41: =[8]Քաղաքային!C57+[8]Քաղաքային!C58+[8]Գյուղական!C39 -> 111178 | D41: =[8]Քաղաքային!D57+[8]Քաղաքային!D58+[8]Գյուղական!D39 -> 111546 | E41: =[8]Քաղաքային!E57+[8]Քաղաքային!E58+[8]Գյուղական!E39 -> 111580 | F41: =[8]Քաղաքային!F57+[8]Քաղաքային!F58+[8]Գյուղական!F39 -> 111720 | G41: =[8]Քաղաքային!G57+[8]Քաղաքային!G58+[8]Գյուղական!G39 -> 111535 | H41: =[8]Քաղաքային!H57+[8]Քաղաքային!H58+[8]Գյուղական!H39 -> 111321 | I41: =[3]Քաղաքային!I57+[3]Քաղաքային!I58+[3]Գյուղական!I39 -> 111000 | J41: =[4]Քաղաքային!J57+[4]Քաղաքային!J58+[4]Գյուղական!J39 -> 111140 | K41: =[5]Քաղաքային!K57+[5]Քաղաքային!K58+[5]Գյուղական!K39 -> 111072 | L41: =[6]Քաղաքային!L57+[6]Քաղաքային!L58+[6]Գյուղական!L39 -> 111420 | M41: =[7]Քաղաքային!M57+[7]Քաղաքային!M58+[7]Գյուղական!M39 -> 111414
A42: Nairi district | B42: =[8]Քաղաքային!B59+[8]Քաղաքային!B60+[8]Գյուղական!B40 -> 57969 | C42: =[8]Քաղաքային!C59+[8]Քաղաքային!C60+[8]Գյուղական!C40 -> 57993 | D42: =[8]Քաղաքային!D59+[8]Քաղաքային!D60+[8]Գյուղական!D40 -> 58227 | E42: =[8]Քաղաքային!E59+[8]Քաղաքային!E60+[8]Գյուղական!E40 -> 58207 | F42: =[8]Քաղաքային!F59+[8]Քաղաքային!F60+[8]Գյուղական!F40 -> 58130 | G42: =[8]Քաղաքային!G59+[8]Քաղաքային!G60+[8]Գյուղական!G40 -> 57933 | H42: =[8]Քաղաքային!H59+[8]Քաղաքային!H60+[8]Գյուղական!H40 -> 57702 | I42: =[3]Քաղաքային!I59+[3]Քաղաքային!I60+[3]Գյուղական!I40 -> 57398 | J42: =[4]Քաղաքային!J59+[4]Քաղաքային!J60+[4]Գյուղական!J40 -> 57329 | K42: =[5]Քաղաքային!K59+[5]Քաղաքային!K60+[5]Գյուղական!K40 -> 57227 | L42: =[6]Քաղաքային!L59+[6]Քաղաքային!L60+[6]Գյուղական!L40 -> 57280 | M42: =[7]Քաղաքային!M59+[7]Քաղաքային!M60+[7]Գյուղական!M40 -> 57206
A44: Shirak Marz | B44: =B45+B46+B47+B48+B49+B50 -> 251941 | C44: =C45+C46+C47+C48+C49+C50 -> 252093 | D44: =D45+D46+D47+D48+D49+D50 -> 251267 | E44: =E45+E46+E47+E48+E49+E50 -> 248381 | F44: =F45+F46+F47+F48+F49+F50 -> 246409 | G44: =G45+G46+G47+G48+G49+G50 -> 243152 | H44: =H45+H46+H47+H48+H49+H50 -> 239278 | I44: =I45+I46+I47+I48+I49+I50 -> 235380 | ... M44: =M45+M46+M47+M48+M49+M50 -> 230340
A45: c.Gyumri (Marz Center) | B45: =[8]Քաղաքային!B63 -> 121976 | C45: =[8]Քաղաքային!C63 -> 121945 | D45: =[8]Քաղաքային!D63 -> 121342 | E45: =[8]Քաղաքային!E63 -> 119885 | F45: =[8]Քաղաքային!F63 -> 119034 | G45: =[8]Քաղաքային!G63 -> 117714 | H45: =[8]Քաղաքային!H63 -> 116031 | I45: =[3]Քաղաքային!I63 -> 114430 | J45: =[4]Քաղաքային!J63 -> 113525 | K45: =[5]Քաղաքային!K63 -> 112412 | L45: =[6]Քաղաքային!L63 -> 112108 | M45: =[7]Քաղաքային!M63 -> 111138
A46: Akhuryan district | B46: =[8]Գյուղական!B43 -> 41546 | C46: =[8]Գյուղական!C43 -> 41598 | D46: =[8]Գյուղական!D43 -> 41433 | E46: =[8]Գյուղական!E43 -> 40925 | F46: =[8]Գյուղական!F43 -> 40409 | G46: =[8]Գյուղական!G43 -> 39612 | H46: =[8]Գյուղական!H43 -> 38772 | I46: =[3]Գյուղական!I43 -> 37889 | J46: =[4]Գյուղական!J43 -> 37411 | K46: =[5]Գյուղական!K43 -> 37137 | L46: =[6]Գյուղական!L43 -> 37178 | M46: =[7]Գյուղական!M43 -> 37348
A47: Amasia district | B47: =[8]Գյուղական!B44 -> 6306 | C47: =[8]Գյուղական!C44 -> 6316 | D47: =[8]Գյուղական!D44 -> 6336 | E47: =[8]Գյուղական!E44 -> 6335 | F47: =[8]Գյուղական!F44 -> 6340 | G47: =[8]Գյուղական!G44 -> 6305 | H47: =[8]Գյուղական!H44 -> 6244 | I47: =[3]Գյուղական!I44 -> 6192 | J47: =[4]Գյուղական!J44 -> 6167 | K47: =[5]Գյուղական!K44 -> 6151 | L47: =[6]Գյուղական!L44 -> 6109 | M47: =[7]Գյուղական!M44 -> 6127
...

Sheet Urbanpopulation
A1: De jure Population number1 of the Republic of Armenia, as of 1 January
A2: URBAN POPULATION
M3: /person/
A4: Marz, district, city/town, administrative districts | B4: 2011 2 | C4: 2012 | D4: 2013 | E4: 2014 | F4: 2015 | G4: 2016 | H4: 2017 | I4: 2018 | J4: 2019 | K4: 2020 | L4: 2021 | M4: 2022
A5: Republic of Armenia | B5: =B6+B20+B25+B31+B36+B43+B53+B62+B67+B76+B81 -> 1911287 | C5: 1912645 | D5: 1917457 | E5: =E6+E20+E25+E31+E36+E43+E53+E62+E67+E76+E81 -> 1914048 | F5: =F6+F20+F25+F31+F36+F43+F53+F62+F67+F76+F81 -> 1912928 | G5: =G6+G20+G25+G31+G36+G43+G53+G62+G67+G76+G81 -> 1907006 | H5: =H6+H20+H25+H31+H36+H43+H53+H62+H67+H76+H81 -> 1901453 | I5: =I6+I20+I25+I31+I36+I43+I53+I62+I67+I76+I81 -> 1895807 | J5: =J6+J20+J25+J31+J36+J43+J53+J62+J67+J76+J81 -> 1894917 | K5: =K6+K20+K25+K31+K36+K43+K53+K62+K67+K76+K81 -> 1892086 | L5: =L6+L20+L25+L31+L36+L43+L53+L62+L67+L76+L81 -> 1895555 | M5: =M6+M20+M25+M31+M36+M43+M53+M62+M67+M76+M81 -> 1892147
A6: city Yerevan | B6: =SUM(B7:B18) -> 1060138 | C6: =SUM(C7:C18) -> 1061044 | D6: =SUM(D7:D18) -> 1066264 | E6: =E7+E8+E9+E10+E11+E12+E13+E14+E15+E16+E17+E18 -> 1068306 | F6: =F7+F8+F9+F10+F11+F12+F13+F14+F15+F16+F17+F18 -> 1071511 | G6: =G7+G8+G9+G10+G11+G12+G13+G14+G15+G16+G17+G18 -> 1073660 | H6: =H7+H8+H9+H10+H11+H12+H13+H14+H15+H16+H17+H18 -> 1075841 | I6: =I7+I8+I9+I10+I11+I12+I13+I14+I15+I16+I17+I18 -> 1077590 | J6: =J7+J8+J9+J10+J11+J12+J13+J14+J15+J16+J17+J18 -> 1081874 | K6: =K7+K8+K9+K10+K11+K12+K13+K14+K15+K16+K17+K18 -> 1084024 | L6: =L7+L8+L9+L10+L11+L12+L13+L14+L15+L16+L17+L18 -> 1091747 | M6: =M7+M8+M9+M10+M11+M12+M13+M14+M15+M16+M17+M18 -> 1092778
A7: Ajapnyak | B7: 108282 | C7: 108358 | D7: 108670 | E7: 108761 | F7: 108953 | G7: 109048 | H7: 109252 | I7: 109265 | J7: 109675 | K7: 109783 | L7: 110503 | M7: 110425
A8: Avan | B8: 53231 | C8: 53218 | D8: 53244 | E8: 53149 | F8: 53137 | G8: 53093 | H8: 52997 | I8: 52898 | J8: 52909 | K8: 52869 | L8: 53155 | M8: 53309
A9: Arabkir | B9: 117704 | C9: 117633 | D9: 117231 | E9: 116716 | F9: 116199 | G9: 115770 | H9: 115386 | I9: 114963 | J9: 114804 | K9: 114461 | L9: 115169 | M9: 114972
A10: Davitashen | B10: 42380 | C10: 42383 | D10: 42458 | E10: 42470 | F10: 42490 | G10: 42480 | H10: 42489 | I10: 42465 | J10: 42528 | K10: 42517 | L10: 43121 | M10: 43324
A11: Erebuni | B11: 123092 | C11: 123261 | D11: 124406 | E11: 124997 | F11: 125827 | G11: 126542 | H11: 127200 | I11: 127779 | J11: 128595 | K11: 129316 | L11: 129966 | M11: 130051
A12: Kentron | B12: 125453 | C12: 125548 | D12: 126020 | E12: 125837 | F12: 125835 | G12: 125674 | H12: 125629 | I12: 125481 | J12: 125722 | K12: 125519 | L12: 126179 | M12: 125875
A13: Malatia-Sebastia | B13: 132900 | C13: 133005 | D13: 133719 | E13: 134365 | F13: 135190 | G13: 135916 | H13: 136679 | I13: 137545 | J13: 138601 | K13: 139345 | L13: 140618 | M13: 141025
A14: Nor-Nork | B14: 126065 | C14: 126280 | D14: 127432 | E14: 128365 | F14: 129456 | G14: 130305 | H14: 131019 | I14: 131674 | J14: 132569 | K14: 133132 | L14: 134048 | M14: 134393
A15: Nork-Marash | B15: 12049 | C15: 12032 | D15: 12006 | E15: 11941 | F15: 11891 | G15: 11835 | H15: 11779 | I15: 11734 | J15: 11693 | K15: 11648 | L15: 11883 | M15: 11942
A16: Nubarashen | B16: 9561 | C16: 9584 | D16: 9710 | E16: 9734 | F16: 9759 | G16: 9807 | H16: 9831 | I16: 9831 | J16: 9859 | K16: 9894 | L16: 10215 | M16: 10399
A17: Shengavit | B17: 135535 | C17: 135826 | D17: 137158 | E17: 137786 | F17: 138558 | G17: 139074 | H17: 139596 | I17: 139983 | J17: 140697 | K17: 141206 | L17: 141960 | M17: 142042
A18: Qanaqer-Zeytun | B18: 73886 | C18: 73916 | D18: 74210 | E18: 74185 | F18: 74216 | G18: 74116 | H18: 73984 | I18: 73972 | J18: 74222 | K18: 74334 | L18: 74930 | M18: 75021
A20: Aragatsotn Marz | B20: =B21+B22+B23 -> 30595 | C20: =C21+C22+C23 -> 30612 | D20: 30631 | E20: =E21+E22+E23 -> 30317 | F20: =F21+F22+F23 -> 29896 | G20: =G21+G22+G23 -> 29049 | H20: =H21+H22+H23 -> 28294 | I20: =I21+I22+I23 -> 27602 | J20: =J21+J22+J23 -> 26983 | K20: =K21+K22+K23 -> 26793 | L20: =L21+L22+L23 -> 26565 | M20: =M21+M22+M23 -> 26545
A21: t.Ashtarak (Marz Center) | B21: 18834 | C21: 18838 | D21: 18868 | E21: 18697 | F21: 18458 | G21: 18005 | H21: 17600 | I21: 17217 | J21: 16878 | K21: 16777 | L21: 16674 | M21: 16630
A22: t.Aparan | B22: 6451 | C22: 6459 | D22: 6469 | E22: 6456 | F22: 6413 | G22: 6291 | H22: 6165 | I22: 6059 | J22: 5958 | K22: 5944 | L22: 5872 | M22: 5873
A23: t.Talin | B23: 5310 | C23: 5315 | D23: 5294 | E23: 5164 | F23: 5025 | G23: 4753 | H23: 4529 | I23: 4326 | J23: 4147 | K23: 4072 | L23: 4019 | M23: 4042
A25: Ararat marz | B25: =B26+B27+B28+B29 -> 74103 | C25: =C26+C27+C28+C29 -> 74184 | D25: 74486 | E25: =E26+E27+E28+E29 -> 74412 | F25: =F26+F27+F28+F29 -> 73976 | G25: =G26+G27+G28+G29 -> 73108 | H25: =H26+H27+H28+H29 -> 72686 | I25: =I26+I27+I28+I29 -> 72384 | J25: =J26+J27+J28+J29 -> 72165 | K25: =K26+K27+K28+K29 -> 72128 | L25: =L26+L27+L28+L29 -> 71946 | M25: =M26+M27+M28+M29 -> 71969
A26: t.Artashat(Marz Center) | B26: 22269 | C26: 22275 | D26: 22285 | E26: 22001 | F26: 21475 | G26: 20679 | H26: 20247 | I26: 19802 | J26: 19406 | K26: 19230 | L26: 19114 | M26: 19083
A27: t.Ararat | B27: 20235 | C27: 20244 | D27: 20306 | E27: 20345 | F27: 20369 | G27: 20366 | H27: 20366 | I27: 20395 | J27: 20421 | K27: 20445 | L27: 20407 | M27: 20385
A28: t.Vedi | B28: 11384 | C28: 11418 | D28: 11502 | E28: 11585 | F28: 11599 | G28: 11579 | H28: 11592 | I28: 11675 | J28: 11762 | K28: 11800 | L28: 11758 | M28: 11799
A29: t.Masis | B29: 20215 | C29: 20247 | D29: 20393 | E29: 20481 | F29: 20533 | G29: 20484 | H29: 20481 | I29: 20512 | J29: 20576 | K29: 20653 | L29: 20667 | M29: 20702
A31: Armavir Marz | B31: =B32+B33+B34 -> 85050 | C31: =C32+C33+C34 -> 85167 | D31: 85280 | E31: =E32+E33+E34 -> 85310 | F31: =F32+F33+F34 -> 84995 | G31: =G32+G33+G34 -> 84622 | H31: =H32+H33+H34 -> 83987 | I31: =I32+I33+I34 -> 83209 | J31: =J32+J33+J34 -> 82663 | K31: =K32+K33+K34 -> 82453 | L31: =L32+L33+L34 -> 82474 | M31: =M32+M33+M34 -> 82522
A32: t.Armavir (Marz Center) | B32: 29319 | C32: 29355 | D32: 29353 | E32: 29287 | F32: 29104 | G32: 28885 | H32: 28563 | I32: 28173 | J32: 27932 | K32: 27833 | L32: 27680 | M32: 27713
A33: t.Metsamor | B33: 9191 | C33: 9208 | D33: 9217 | E33: 9204 | F33: 9107 | G33: 8988 | H33: 8816 | I33: 8630 | J33: 8487 | K33: 8411 | L33: 8406 | M33: 8453
A34: c.Vagharshaapat | B34: 46540 | C34: 46604 | D34: 46710 | E34: 46819 | F34: 46784 | G34: 46749 | H34: 46608 | I34: 46406 | J34: 46244 | K34: 46209 | L34: 46388 | M34: 46356
A36: Gegarkunik Marz | B36: =B37+B38+B39+B40+B41 -> 71423 | C36: =C37+C38+C39+C40+C41 -> 71456 | D36: 71342 | E36: =E37+E38+E39+E40+E41 -> 70800 | F36: =F37+F38+F39+F40+F41 -> 70194 | G36: =G37+G38+G39+G40+G41 -> 69180 | H36: =H37+H38+H39+H40+H41 -> 68373 | I36: =I37+I38+I39+I40+I41 -> 67692 | J36: =J37+J38+J39+J40+J41 -> 66978 | K36: =K37+K38+K39+K40+K41 -> 66548 | L36: =L37+L38+L39+L40+L41 -> 66213 | M36: =M37+M38+M39+M40+M41 -> 65916
A37: t.Gavar (Marz Center) | B37: 20765 | C37: 20759 | D37: 20626 | E37: 20346 | F37: 20001 | G37: 19490 | H37: 19069 | I37: 18721 | J37: 18358 | K37: 18082 | L37: 17968 | M37: 17830
A38: t.Chambarak | B38: 5850 | C38: 5849 | D38: 5844 | E38: 5810 | F38: 5784 | G38: 5715 | H38: 5691 | I38: 5652 | J38: 5602 | K38: 5570 | L38: 5495 | M38: 5495
A39: t.Martuni | B39: 12894 | C39: 12916 | D39: 12879 | E39: 12698 | F39: 12509 | G39: 12209 | H39: 11960 | I39: 11739 | J39: 11553 | K39: 11443 | L39: 11428 | M39: 11399
A40: t.Sevan | B40: 19229 | C40: 19251 | D40: 19292 | E40: 19281 | F40: 19254 | G40: 19169 | H40: 19103 | I40: 19079 | J40: 19012 | K40: 19010 | L40: 18959 | M40: 18870
A41: t.Vardenis | B41: 12685 | C41: 12681 | D41: 12701 | E41: 12665 | F41: 12646 | G41: 12597 | H41: 12550 | I41: 12501 | J41: 12453 | K41: 12443 | L41: 12363 | M41: 12322
A43: Lori Marz | B43: =B44+B45+B46+B47+B48+B49+B50+B51 -> 137784 | C43: =C44+C45+C46+C47+C48+C49+C50+C51 -> 137818 | D43: 137211 | E43: =E44+E45+E46+E47+E48+E49+E50+E51 -> 135434 | F43: =F44+F45+F46+F47+F48+F49+F50+F51 -> 134310 | G43: =G44+G45+G46+G47+G48+G49+G50+G51 -> 132807 | H43: =H44+H45+H46+H47+H48+H49+H50+H51 -> 130766 | I43: =I44+I45+I46+I47+I48+I49+I50+I51 -> 128844 | J43: =J44+J45+J46+J47+J48+J49+J50+J51 -> 127585 | K43: =K44+K45+K46+K47+K48+K49+K50+K51 -> 126073 | L43: =L44+L45+L46+L47+L48+L49+L50+L51 -> 125387 | M43: =M44+M45+M46+M47+M48+M49+M50+M51 -> 124470
A44: c.Vanadzor (Marz Center) | B44: 86199 | C44: 86202 | D44: 85673 | E44: 84298 | F44: 83385 | G44: 82221 | H44: 80703 | I44: 79310 | J44: 78386 | K44: 77234 | L44: 76860 | M44: 76220
A45: t.Alaverdi | B45: 13343 | C45: 13329 | D45: 13278 | E45: 13184 | F45: 13099 | G45: 13010 | H45: 12900 | I45: 12740 | J45: 12641 | K45: 12543 | L45: 12361 | M45: 12238
...

Sheet Ruralpopulation
A1: De jure Population number 1 of the Republic of Armenia, as of 1 January
A2: RURAL POPULATION
M3: /person/
A4: Marz, district | B4: 2011 2 | C4: 2012 | D4: 2013 | E4: 2014 | F4: 2015 | G4: 2016 | H4: 2017 | I4: 2018 | J4: 2019 | K4: 2020 | L4: 2021 | M4: 2022
A5: Republic of Armenia | B5: =B7+B13+B18+B23+B30+B37+B42+B49+B55+B59 -> 1107567 | C5: =C7+C13+C18+C23+C30+C37+C42+C49+C55+C59 -> 1108721 | D5: =D7+D13+D18+D23+D30+D37+D42+D49+D55+D59 -> 1109412 | E5: =E7+E13+E18+E23+E30+E37+E42+E49+E55+E59 -> 1103031 | F5: =F7+F13+F18+F23+F30+F37+F42+F49+F55+F59 -> 1097670 | G5: =G7+G13+G18+G23+G30+G37+G42+G49+G55+G59 -> 1091571 | H5: =H7+H13+H18+H23+H30+H37+H42+H49+H55+H59 -> 1084698 | I5: =I7+I13+I18+I23+I30+I37+I42+I49+I55+I59 -> 1076925 | ... M5: =M7+M13+M18+M23+M30+M37+M42+M49+M55+M59 -> 1069220
A7: Aragatsotn Marz | B7: =SUM(B8:B11) -> 102330 | C7: =SUM(C8:C11) -> 102451 | D7: =SUM(D8:D11) -> 102439 | E7: =SUM(E8:E11) -> 101988 | F7: =SUM(F8:F11) -> 101436 | G7: =SUM(G8:G11) -> 100725 | H7: =SUM(H8:H11) -> 100224 | I7: =SUM(I8:I11) -> 99544 | ... M7: =SUM(M8:M11) -> 98101
A8: Ashtarak district | B8: 45453 | C8: 45487 | D8: 45306 | E8: 44849 | F8: 44301 | G8: 43704 | H8: 43234 | I8: 42699 | J8: 41921 | K8: 41545 | L8: 41587 | M8: 41689
A9: Aparan district | B9: 15578 | C9: 15603 | D9: 15649 | E9: 15625 | F9: 15562 | G9: 15479 | H9: 15458 | I9: 15387 | J9: 15226 | K9: 15184 | L9: 15199 | M9: 15249
A10: Aragats district | B10: 13250 | C10: 13276 | D10: 13361 | E10: 13378 | F10: 13448 | G10: 13485 | H10: 13530 | I10: 13553 | J10: 13522 | K10: 13526 | L10: 13463 | M10: 13494
A11: Talin district | B11: 28049 | C11: 28085 | D11: 28123 | E11: 28136 | F11: 28125 | G11: 28057 | H11: 28002 | I11: 27905 | J11: 27788 | K11: 27673 | L11: 27632 | M11: 27669
A13: Ararat marz | B13: =SUM(B14:B16) -> 186264 | C13: =SUM(C14:C16) -> 186450 | D13: =SUM(D14:D16) -> 186849 | E13: =SUM(E14:E16) -> 186375 | F13: =SUM(F14:F16) -> 186126 | G13: =SUM(G14:G16) -> 185803 | H13: =SUM(H14:H16) -> 185721 | I13: =SUM(I14:I16) -> 185420 | ... M13: =SUM(M14:M16) -> 184646
A14: Artashat district | B14: 70744 | C14: 70797 | D14: 70761 | E14: 70320 | F14: 70062 | G14: 69730 | H14: 69557 | I14: 69268 | J14: 68712 | K14: 68590 | L14: 68519 | M14: 68393
A15: Ararat district | B15: 57293 | C15: 57409 | D15: 57701 | E15: 57649 | F15: 57609 | G15: 57581 | H15: 57659 | I15: 57689 | J15: 57443 | K15: 57449 | L15: 57510 | M15: 57537
A16: Masis district | B16: 58227 | C16: 58244 | D16: 58387 | E16: 58406 | F16: 58455 | G16: 58492 | H16: 58505 | I16: 58463 | J16: 58368 | K16: 58403 | L16: 58655 | M16: 58716
A18: Armavir Marz | B18: =SUM(B19:B21) -> 180720 | C18: =SUM(C19:C21) -> 180984 | D18: =SUM(D19:D21) -> 181821 | E18: =SUM(E19:E21) -> 181877 | F18: =SUM(F19:F21) -> 182007 | G18: =SUM(G19:G21) -> 181991 | H18: =SUM(H19:H21) -> 181772 | I18: =SUM(I19:I21) -> 181408 | ... M18: =SUM(M19:M21) -> 181861
A19: Armavir district | B19: 73582 | C19: 73702 | D19: 74121 | E19: 74393 | F19: 74610 | G19: 74709 | H19: 74810 | I19: 74890 | J19: 75040 | K19: 75235 | L19: 75261 | M19: 75559
A20: Baghramyan district | B20: 20291 | C20: 20336 | D20: 20415 | E20: 20190 | F20: 20071 | G20: 19973 | H20: 19721 | I20: 19506 | J20: 19302 | K20: 19230 | L20: 19198 | M20: 19165
A21: Echmiatsin district | B21: 86847 | C21: 86946 | D21: 87285 | E21: 87294 | F21: 87326 | G21: 87309 | H21: 87241 | I21: 87012 | J21: 86895 | K21: 86945 | L21: 87011 | M21: 87137
A23: Gegarkunik Marz | B23: =SUM(B24:B28) -> 163652 | C23: =SUM(C24:C28) -> 163924 | D23: =SUM(D24:D28) -> 164245 | E23: =SUM(E24:E28) -> 163279 | F23: =SUM(F24:F28) -> 162794 | G23: =SUM(G24:G28) -> 162614 | H23: =SUM(H24:H28) -> 162342 | I23: =SUM(I24:I28) -> 162019 | ... M23: =SUM(M24:M28) -> 161862
A24: Gavar district | B24: 31922 | C24: 31968 | D24: 31975 | E24: 31644 | F24: 31419 | G24: 31254 | H24: 31107 | I24: 30938 | J24: 30681 | K24: 30543 | L24: 30504 | M24: 30610
A25: Chambarak district | B25: 7938 | C25: 7926 | D25: 7899 | E25: 7832 | F25: 7774 | G25: 7751 | H25: 7704 | I25: 7689 | J25: 7641 | K25: 7597 | L25: 7561 | M25: 7594
A26: Martuni district | B26: 77330 | C26: 77545 | D26: 77781 | E26: 77419 | F26: 77349 | G26: 77393 | H26: 77343 | I26: 77289 | J26: 77070 | K26: 77110 | L26: 77279 | M26: 77751
A27: Sevan district | B27: 20547 | C27: 20590 | D27: 20727 | E27: 20740 | F27: 20781 | G27: 20841 | H27: 20883 | I27: 20893 | J27: 20887 | K27: 20897 | L27: 20914 | M27: 20986
A28: Vardenis district | B28: 25915 | C28: 25895 | D28: 25863 | E28: 25644 | F28: 25471 | G28: 25375 | H28: 25305 | I28: 25210 | J28: 24999 | K28: 24937 | L28: 24798 | M28: 24921
A30: Lori Marz | B30: =SUM(B31:B35) -> 97753 | C30: =SUM(C31:C35) -> 97842 | D30: =SUM(D31:D35) -> 97452 | E30: =SUM(E31:E35) -> 95326 | F30: =SUM(F31:F35) -> 93689 | G30: =SUM(G31:G35) -> 92147 | H30: =SUM(H31:H35) -> 90332 | I30: =SUM(I31:I35) -> 88519 | ... M30: =SUM(M31:M35) -> 87207
A31: Gugarq district | B31: 22675 | C31: 22675 | D31: 22462 | E31: 21755 | F31: 21184 | G31: 20634 | H31: 20018 | I31: 19411 | J31: 19158 | K31: 18967 | L31: 19012 | M31: 19008
A32: Tumanyan district | B32: 22161 | C32: 22141 | D32: 22138 | E32: 21970 | F32: 21887 | G32: 21822 | H32: 21699 | I32: 21565 | J32: 21486 | K32: 21389 | L32: 21350 | M32: 21327
A33: Spitak district | B33: 23349 | C33: 23413 | D33: 23475 | E33: 23301 | F33: 23209 | G33: 23119 | H33: 22945 | I33: 22785 | J33: 22820 | K33: 22810 | L33: 22735 | M33: 22808
A34: Stepanavan district | B34: 15156 | C34: 15164 | D34: 15109 | E34: 14774 | F34: 14518 | G34: 14282 | H34: 14017 | I34: 13766 | J34: 13683 | K34: 13588 | L34: 13582 | M34: 13564
A35: Tashir district | B35: 14412 | C35: 14449 | D35: 14268 | E35: 13526 | F35: 12891 | G35: 12290 | H35: 11653 | I35: 10992 | J35: 10739 | K35: 10488 | L35: 10500 | M35: 10500
A37: Kotayk Marz | B37: =SUM(B38:B40) -> 116916 | C37: =SUM(C38:C40) -> 116981 | D37: =SUM(D38:D40) -> 117129 | E37: =SUM(E38:E40) -> 116850 | F37: =SUM(F38:F40) -> 116525 | G37: =SUM(G38:G40) -> 116027 | H37: =SUM(H38:H40) -> 115326 | I37: =SUM(I38:I40) -> 114481 | ... M37: =SUM(M38:M40) -> 114116
A38: Hrazdan district | B38: 21845 | C38: 21871 | D38: 21873 | E38: 21726 | F38: 21691 | G38: 21556 | H38: 21326 | I38: 21081 | J38: 20993 | K38: 20987 | L38: 21088 | M38: 20966
A39: Kotayk district | B39: 58081 | C39: 58108 | D39: 58148 | E39: 58076 | F39: 57934 | G39: 57770 | H39: 57521 | I39: 57200 | J39: 57117 | K39: 57072 | L39: 57346 | M39: 57247
A40: Nairi district | B40: 36990 | C40: 37002 | D40: 37108 | E40: 37048 | F40: 36900 | G40: 36701 | H40: 36479 | I40: 36200 | J40: 36088 | K40: 36013 | L40: 35991 | M40: 35903
A42: Shirak Marz | B42: =SUM(B43:B47) -> 105033 | C42: =SUM(C43:C47) -> 105197 | D42: =SUM(D43:D47) -> 105001 | E42: =SUM(E43:E47) -> 103866 | F42: =SUM(F43:F47) -> 102884 | G42: =SUM(G43:G47) -> 101189 | H42: =SUM(H43:H47) -> 99371 | I42: =SUM(I43:I47) -> 97417 | ... M42: =SUM(M43:M47) -> 96266
A43: Akhuryan district | B43: 41546 | C43: 41598 | D43: 41433 | E43: 40925 | F43: 40409 | G43: 39612 | H43: 38772 | I43: 37889 | J43: 37411 | K43: 37137 | L43: 37178 | M43: 37348
A44: Amasia district | B44: 6306 | C44: 6316 | D44: 6336 | E44: 6335 | F44: 6340 | G44: 6305 | H44: 6244 | I44: 6192 | J44: 6167 | K44: 6151 | L44: 6109 | M44: 6127
A45: Ashotsk district | B45: 9090 | C45: 9099 | D45: 9161 | E45: 9214 | F45: 9261 | G45: 9281 | H45: 9308 | I45: 9287 | J45: 9270 | K45: 9286 | L45: 9242 | M45: 9257
A46: Ani district | B46: 13560 | C46: 13584 | D46: 13671 | E46: 13625 | F46: 13625 | G46: 13559 | H46: 13473 | I46: 13377 | J46: 13352 | K46: 13338 | L46: 13343 | M46: 13414
A47: Artik district | B47: 34531 | C47: 34600 | D47: 34400 | E47: 33767 | F47: 33249 | G47: 32432 | H47: 31574 | I47: 30672 | J47: 30149 | K47: 29883 | L47: 29910 | M47: 30120
...
